Workbook

Sheet Income Statement
A1: Company Fundamentals - Income Statement
A2: Company Name | B2: Wesfarmers Ltd (WES.AX)
A3: Country of Exchange | B3: Australia
A4: Country of Headquarters | B4: Australia
A5: TRBC Industry Group | B5: Diversified Retail
A6: CF Template | B6: IND
A7: Consolidation Basis | B7: Consolidated
A8: Scaling | B8: Millions
A9: Period | B9: Annual
A10: Export Date | B10: 46164.123
A11: Statement Data | B11: 2025 | C11: 2024 | D11: 2023 | E11: 2022 | F11: 2021
A12: Period End Date | B12: 45838 | C12: 45473 | D12: 45107 | E12: 44742 | F12: 44377
A13: Statement Date | B13: 45838 | C13: 45473 | D13: 45107 | E13: 44742 | F13: 44377
A14: Standardized Currency | B14: AUD | C14: AUD | D14: AUD | E14: AUD | F14: AUD
A15: Template Type | B15: Industrial - Operating | C15: Industrial - Operating | D15: Industrial - Operating | E15: Industrial - Operating | F15: Industrial - Operating
A17: Income Statement - Standardized (Currency: Standardized)
A18: Field Name | B18: 30-06-2025 | C18: 30-06-2024 | D18: 30-06-2023 | E18: 30-06-2022 | F18: 30-06-2021 | G18: % Rev 2025 | H18: Avg % Rev | I18: Formula Description | J18: Excel Formula | K18: F2026 | L18: F2027 | M18: F2028 | N18: F2029 | O18: F2030 | P18: % Rev 2024 | Q18: % Rev 2023 | R18: % Rev 2022 | S18: % Rev 2021
A19: Revenues
A20: Revenue from Goods & Services | B20: 45576 | C20: 44047 | D20: 43417 | E20: 36679 | F20: 33797 | G20: =IFERROR(B20/B25,"") -> 0.99728665 | H20: =IFERROR(AVERAGE(G20,P20,Q20,R20,S20),"") -> 0.99649207 | I20: Avg % of total revenue | J20: H20*K25 | K20: =ROUND(H20*K25,0) -> 49928 | L20: =ROUND(H20*L25,0) -> 53004 | M20: =ROUND(H20*M25,0) -> 56081 | N20: =ROUND(H20*N25,0) -> 59157 | O20: =ROUND(H20*O25,0) -> 62233 | P20: =IFERROR(C20/C25,"") -> 0.99678653 | Q20: =IFERROR(D20/D25,"") -> 0.99694604 | R20: =IFERROR(E20/E25,"") -> 0.9956838 | S20: =IFERROR(F20/F25,"") -> 0.99575734
A21: Sales of Goods & Services - Net - Unclassified | B21: 45576 | C21: 44047 | D21: 43417 | E21: 36679 | F21: 33797 | G21: =IFERROR(B21/B25,"") -> 0.99728665 | H21: =IFERROR(AVERAGE(G21,P21,Q21,R21,S21),"") -> 0.99649207 | I21: row 20 (same item, different classification) | J21: K20 | K21: =K20 -> 49928 | L21: =L20 -> 53004 | M21: =M20 -> 56081 | N21: =N20 -> 59157 | O21: =O20 -> 62233 | P21: =IFERROR(C21/C25,"") -> 0.99678653 | Q21: =IFERROR(D21/D25,"") -> 0.99694604 | R21: =IFERROR(E21/E25,"") -> 0.9956838 | S21: =IFERROR(F21/F25,"") -> 0.99575734
A22: Revenue from Financing-Related Operations | B22: 38 | C22: 47 | D22: 41 | E22: 59 | F22: 51 | G22: =IFERROR(B22/B25,"") -> 0.00083150985 | H22: =IFERROR(AVERAGE(G22,P22,Q22,R22,S22),"") -> 0.0011881568 | I22: Avg % of total revenue | J22: H22*K25 | K22: =ROUND(H22*K25,0) -> 60 | L22: =ROUND(H22*L25,0) -> 63 | M22: =ROUND(H22*M25,0) -> 67 | N22: =ROUND(H22*N25,0) -> 71 | O22: =ROUND(H22*O25,0) -> 74 | P22: =IFERROR(C22/C25,"") -> 0.0010636131 | Q22: =IFERROR(D22/D25,"") -> 0.00094144661 | R22: =IFERROR(E22/E25,"") -> 0.001601607 | S22: =IFERROR(F22/F25,"") -> 0.0015026075
A23: Business-Related Financing Revenue - Other | B23: 38 | C23: 47 | D23: 41 | E23: 59 | F23: 51 | G23: =IFERROR(B23/B25,"") -> 0.00083150985 | H23: =IFERROR(AVERAGE(G23,P23,Q23,R23,S23),"") -> 0.0011881568 | I23: row 22 (same item, different classification) | J23: K22 | K23: =K22 -> 60 | L23: =L22 -> 63 | M23: =M22 -> 67 | N23: =N22 -> 71 | O23: =O22 -> 74 | P23: =IFERROR(C23/C25,"") -> 0.0010636131 | Q23: =IFERROR(D23/D25,"") -> 0.00094144661 | R23: =IFERROR(E23/E25,"") -> 0.001601607 | S23: =IFERROR(F23/F25,"") -> 0.0015026075
A24: Revenue from Business-Related Activities - Other - Total | B24: 86 | C24: 95 | D24: 92 | E24: 100 | F24: 93 | G24: =IFERROR(B24/B25,"") -> 0.0018818381 | H24: =IFERROR(AVERAGE(G24,P24,Q24,R24,S24),"") -> 0.0023197692 | I24: Avg % of total revenue | J24: H24*K25 | K24: =ROUND(H24*K25,0) -> 116 | L24: =ROUND(H24*L25,0) -> 123 | M24: =ROUND(H24*M25,0) -> 131 | N24: =ROUND(H24*N25,0) -> 138 | O24: =ROUND(H24*O25,0) -> 145 | P24: =IFERROR(C24/C25,"") -> 0.0021498563 | Q24: =IFERROR(D24/D25,"") -> 0.0021125144 | R24: =IFERROR(E24/E25,"") -> 0.0027145882 | S24: =IFERROR(F24/F25,"") -> 0.0027400489
A25: Revenue from Business Activities - Total | B25: =B20+B22+B24 -> 45700 | C25: =C20+C22+C24 -> 44189 | D25: =D20+D22+D24 -> 43550 | E25: =E20+E22+E24 -> 36838 | F25: =F20+F22+F24 -> 33941 | G25: =IFERROR(B25/B25,"") -> 1 | H25: =IFERROR(AVERAGE(G25,P25,Q25,R25,S25),"") -> 1 | I25: Regression on Year (OLS, see Analysis sheet) | J25: alpha + slope*year [R²=0.9007] | K25: 50104 | L25: 53191 | M25: 56278 | N25: 59365 | O25: 62452 | P25: =IFERROR(C25/C25,"") -> 1 | Q25: =IFERROR(D25/D25,"") -> 1 | R25: =IFERROR(E25/E25,"") -> 1 | S25: =IFERROR(F25/F25,"") -> 1
A26: Operating Expenses
A27: Cost of Operating Revenue | B27: 31772 | C27: 30628 | D27: 30606 | E27: 25013 | F27: 22386 | G27: =IFERROR(B27/B25,"") -> 0.69522976 | H27: =IFERROR(AVERAGE(G27,P27,Q27,R27,S27),"") -> 0.68593562 | I27: Avg % of total revenue | J27: H27*K25 | K27: =ROUND(H27*K25,0) -> 34368 | L27: =ROUND(H27*L25,0) -> 36486 | M27: =ROUND(H27*M25,0) -> 38603 | N27: =ROUND(H27*N25,0) -> 40721 | O27: =ROUND(H27*O25,0) -> 42838 | P27: =IFERROR(C27/C25,"") -> 0.69311367 | Q27: =IFERROR(D27/D25,"") -> 0.70277842 | R27: =IFERROR(E27/E25,"") -> 0.67899995 | S27: =IFERROR(F27/F25,"") -> 0.65955629
A28: Cost of Revenues - Total | B28: =B27 -> 31772 | C28: =C27 -> 30628 | D28: =D27 -> 30606 | E28: =E27 -> 25013 | F28: =F27 -> 22386 | G28: =IFERROR(B28/B25,"") -> 0.69522976 | H28: =IFERROR(AVERAGE(G28,P28,Q28,R28,S28),"") -> 0.68593562 | I28: row 27 (same item, different classification) | J28: K27 | K28: =K27 -> 34368 | L28: =L27 -> 36486 | M28: =M27 -> 38603 | N28: =N27 -> 40721 | O28: =O27 -> 42838 | P28: =IFERROR(C28/C25,"") -> 0.69311367 | Q28: =IFERROR(D28/D25,"") -> 0.70277842 | R28: =IFERROR(E28/E25,"") -> 0.67899995 | S28: =IFERROR(F28/F25,"") -> 0.65955629
A29: Amortization in Cost of Revenues | B29: 125 | C29: 128 | D29: 191 | E29: 158 | F29: 144 | G29: =IFERROR(B29/B25,"") -> 0.0027352298 | H29: =IFERROR(AVERAGE(G29,P29,Q29,R29,S29),"") -> 0.0037098695 | I29: Avg % of total revenue | J29: H29*K25 | K29: =ROUND(H29*K25,0) -> 186 | L29: =ROUND(H29*L25,0) -> 197 | M29: =ROUND(H29*M25,0) -> 209 | N29: =ROUND(H29*N25,0) -> 220 | O29: =ROUND(H29*O25,0) -> 232 | P29: =IFERROR(C29/C25,"") -> 0.0028966485 | Q29: =IFERROR(D29/D25,"") -> 0.0043857635 | R29: =IFERROR(E29/E25,"") -> 0.0042890494 | S29: =IFERROR(F29/F25,"") -> 0.0042426564
A30: Depreciation in Cost of Revenues | B30: 1708 | C30: 1672 | D30: 1510 | E30: 1417 | F30: 1365 | G30: =IFERROR(B30/B25,"") -> 0.037374179 | H30: =IFERROR(AVERAGE(G30,P30,Q30,R30,S30),"") -> 0.0377134 | I30: Avg dep rate × PPE_net_{t-1} (from BS) | J30: 0.1453×PPE_net_{t-1} (Balance Sheet row 41) | K30: =ROUND(0.1453*'Balance Sheet'!G41,0) -> 1604 | L30: =ROUND(0.1453*'Balance Sheet'!T41,0) -> 1671 | M30: =ROUND(0.1453*'Balance Sheet'!U41,0) -> 1747 | N30: =ROUND(0.1453*'Balance Sheet'!V41,0) -> 1830 | O30: =ROUND(0.1453*'Balance Sheet'!W41,0) -> 1919 | P30: =IFERROR(C30/C25,"") -> 0.037837471 | Q30: =IFERROR(D30/D25,"") -> 0.03467279 | R30: =IFERROR(E30/E25,"") -> 0.038465715 | S30: =IFERROR(F30/F25,"") -> 0.040216847
A31: Material Expenses | B31: 29939 | C31: 28828 | D31: 28905 | E31: 23438 | F31: 20877 | G31: =IFERROR(B31/B25,"") -> 0.65512035 | H31: =IFERROR(AVERAGE(G31,P31,Q31,R31,S31),"") -> 0.64451235 | I31: Avg % of total revenue | J31: H31*K25 | K31: =ROUND(H31*K25,0) -> 32293 | L31: =ROUND(H31*L25,0) -> 34282 | M31: =ROUND(H31*M25,0) -> 36272 | N31: =ROUND(H31*N25,0) -> 38261 | O31: =ROUND(H31*O25,0) -> 40251 | P31: =IFERROR(C31/C25,"") -> 0.65237955 | Q31: =IFERROR(D31/D25,"") -> 0.66371986 | R31: =IFERROR(E31/E25,"") -> 0.63624518 | S31: =IFERROR(F31/F25,"") -> 0.61509679
A32: Material Expenses - Materials, Inventory, Own Work & Utility - Unclassified | B32: 29939 | C32: 28828 | D32: 28905 | E32: 23438 | F32: 20877 | G32: =IFERROR(B32/B25,"") -> 0.65512035 | H32: =IFERROR(AVERAGE(G32,P32,Q32,R32,S32),"") -> 0.64451235 | I32: row 31 (same item, different classification) | J32: K31 | K32: =K31 -> 32293 | L32: =L31 -> 34282 | M32: =M31 -> 36272 | N32: =N31 -> 38261 | O32: =O31 -> 40251 | P32: =IFERROR(C32/C25,"") -> 0.65237955 | Q32: =IFERROR(D32/D25,"") -> 0.66371986 | R32: =IFERROR(E32/E25,"") -> 0.63624518 | S32: =IFERROR(F32/F25,"") -> 0.61509679
A33: Gross Profit - Industrials/Property - Total | B33: =B25-B28 -> 13928 | C33: =C25-C28 -> 13561 | D33: =D25-D28 -> 12944 | E33: =E25-E28 -> 11825 | F33: =F25-F28 -> 11555 | G33: =IFERROR(B33/B25,"") -> 0.30477024 | H33: =IFERROR(AVERAGE(G33,P33,Q33,R33,S33),"") -> 0.31406438 | I33: Revenue Total – Cost of Revenues | J33: K25-K28 | K33: =K25-K28 -> 15736 | L33: =L25-L28 -> 16705 | M33: =M25-M28 -> 17675 | N33: =N25-N28 -> 18644 | O33: =O25-O28 -> 19614 | P33: =IFERROR(C33/C25,"") -> 0.30688633 | Q33: =IFERROR(D33/D25,"") -> 0.29722158 | R33: =IFERROR(E33/E25,"") -> 0.32100005 | S33: =IFERROR(F33/F25,"") -> 0.34044371
A34: Selling, General & Administrative Expenses - Total | B34: =B35+B36+B37+B38 -> 8886 | C34: =C35+C36+C37+C38 -> 8191 | D34: =D35+D36+D37+D38 -> 7879 | E34: =E35+E36+E37+E38 -> 7230 | F34: =F35+F36+F37+F38 -> 6764 | G34: =IFERROR(B34/B25,"") -> 0.19444201 | H34: =IFERROR(AVERAGE(G34,P34,Q34,R34,S34),"") -> 0.19125502 | I34: Avg % of total revenue | J34: H34*K25 | K34: =ROUND(H34*K25,0) -> 9583 | L34: =ROUND(H34*L25,0) -> 10173 | M34: =ROUND(H34*M25,0) -> 10763 | N34: =ROUND(H34*N25,0) -> 11354 | O34: =ROUND(H34*O25,0) -> 11944 | P34: =IFERROR(C34/C25,"") -> 0.18536287 | Q34: =IFERROR(D34/D25,"") -> 0.18091848 | R34: =IFERROR(E34/E25,"") -> 0.19626473 | S34: =IFERROR(F34/F25,"") -> 0.199287
A35: Selling, General & Administrative Expenses - Unclassified | B35: 840 | C35: 687 | D35: 704 | E35: 668 | F35: 540 | G35: =IFERROR(B35/B25,"") -> 0.018380744 | H35: =IFERROR(AVERAGE(G35,P35,Q35,R35,S35),"") -> 0.016827267 | I35: Avg % of total revenue | J35: H35*K25 | K35: =ROUND(H35*K25,0) -> 843 | L35: =ROUND(H35*L25,0) -> 895 | M35: =ROUND(H35*M25,0) -> 947 | N35: =ROUND(H35*N25,0) -> 999 | O35: =ROUND(H35*O25,0) -> 1051 | P35: =IFERROR(C35/C25,"") -> 0.015546856 | Q35: =IFERROR(D35/D25,"") -> 0.016165327 | R35: =IFERROR(E35/E25,"") -> 0.018133449 | S35: =IFERROR(F35/F25,"") -> 0.015909961
A36: Labor & Related Expenses including Stock-Based Compensation in Selling, General & Administrative Expenses | B36: 6842 | C36: 6639 | D36: 6333 | E36: 5840 | F36: 5500 | G36: =IFERROR(B36/B25,"") -> 0.14971554 | H36: =IFERROR(AVERAGE(G36,P36,Q36,R36,S36),"") -> 0.15319069 | I36: Avg % of total revenue | J36: H36*K25 | K36: =ROUND(H36*K25,0) -> 7675 | L36: =ROUND(H36*L25,0) -> 8148 | M36: =ROUND(H36*M25,0) -> 8621 | N36: =ROUND(H36*N25,0) -> 9094 | O36: =ROUND(H36*O25,0) -> 9567 | P36: =IFERROR(C36/C25,"") -> 0.15024101 | Q36: =IFERROR(D36/D25,"") -> 0.14541906 | R36: =IFERROR(E36/E25,"") -> 0.15853195 | S36: =IFERROR(F36/F25,"") -> 0.1620459
A37: Operations & Maintenance (Utility) | B37: 638 | C37: 319 | D37: 315 | E37: 268 | F37: 247 | G37: =IFERROR(B37/B25,"") -> 0.013960613 | H37: =IFERROR(AVERAGE(G37,P37,Q37,R37,S37),"") -> 0.00859302 | I37: Avg % of total revenue | J37: H37*K25 | K37: =ROUND(H37*K25,0) -> 431 | L37: =ROUND(H37*L25,0) -> 457 | M37: =ROUND(H37*M25,0) -> 484 | N37: =ROUND(H37*N25,0) -> 510 | O37: =ROUND(H37*O25,0) -> 537 | P37: =IFERROR(C37/C25,"") -> 0.0072189912 | Q37: =IFERROR(D37/D25,"") -> 0.0072330654 | R37: =IFERROR(E37/E25,"") -> 0.0072750964 | S37: =IFERROR(F37/F25,"") -> 0.0072773342
A38: Selling, General & Administrative Expenses - Other - Total | B38: 566 | C38: 546 | D38: 527 | E38: 454 | F38: 477 | G38: =IFERROR(B38/B25,"") -> 0.01238512 | H38: =IFERROR(AVERAGE(G38,P38,Q38,R38,S38),"") -> 0.01264404 | I38: Avg % of total revenue | J38: H38*K25 | K38: =ROUND(H38*K25,0) -> 634 | L38: =ROUND(H38*L25,0) -> 673 | M38: =ROUND(H38*M25,0) -> 712 | N38: =ROUND(H38*N25,0) -> 751 | O38: =ROUND(H38*O25,0) -> 790 | P38: =IFERROR(C38/C25,"") -> 0.012356016 | Q38: =IFERROR(D38/D25,"") -> 0.012101033 | R38: =IFERROR(E38/E25,"") -> 0.01232423 | S38: =IFERROR(F38/F25,"") -> 0.014053799
A39: Rental Expense | B39: 48 | C39: 41 | D39: 35 | E39: 58 | G39: =IFERROR(B39/B25,"") -> 0.0010503282 | H39: =IFERROR(AVERAGE(G39,P39,Q39,R39,S39),"") -> 0.00087125921 | I39: Avg % of total revenue | J39: H39*K25 | K39: =ROUND(H39*K25,0) -> 44 | L39: =ROUND(H39*L25,0) -> 46 | M39: =ROUND(H39*M25,0) -> 49 | N39: =ROUND(H39*N25,0) -> 52 | O39: =ROUND(H39*O25,0) -> 54 | P39: =IFERROR(C39/C25,"") -> 0.00092783272 | Q39: =IFERROR(D39/D25,"") -> 0.00080367394 | R39: =IFERROR(E39/E25,"") -> 0.0015744612 | S39: =IFERROR(F39/F25,"") -> 0
A40: Occupancy Expense - Other | B40: 513 | C40: 500 | D40: 470 | E40: 384 | F40: 461 | G40: =IFERROR(B40/B25,"") -> 0.011225383 | H40: =IFERROR(AVERAGE(G40,P40,Q40,R40,S40),"") -> 0.011467804 | I40: Avg % of total revenue | J40: H40*K25 | K40: =ROUND(H40*K25,0) -> 575 | L40: =ROUND(H40*L25,0) -> 610 | M40: =ROUND(H40*M25,0) -> 645 | N40: =ROUND(H40*N25,0) -> 681 | O40: =ROUND(H40*O25,0) -> 716 | P40: =IFERROR(C40/C25,"") -> 0.011315033 | Q40: =IFERROR(D40/D25,"") -> 0.010792193 | R40: =IFERROR(E40/E25,"") -> 0.010424019 | S40: =IFERROR(F40/F25,"") -> 0.013582393
A41: Provision for Doubtful Accounts & Write-off | B41: 5 | C41: 5 | D41: 22 | E41: 12 | F41: 16 | G41: =IFERROR(B41/B25,"") -> 0.00010940919 | H41: =IFERROR(AVERAGE(G41,P41,Q41,R41,S41),"") -> 0.00030497657 | I41: Avg % of total revenue | J41: H41*K25 | K41: =ROUND(H41*K25,0) -> 15 | L41: =ROUND(H41*L25,0) -> 16 | M41: =ROUND(H41*M25,0) -> 17 | N41: =ROUND(H41*N25,0) -> 18 | O41: =ROUND(H41*O25,0) -> 19 | P41: =IFERROR(C41/C25,"") -> 0.00011315033 | Q41: =IFERROR(D41/D25,"") -> 0.00050516648 | R41: =IFERROR(E41/E25,"") -> 0.00032575058 | S41: =IFERROR(F41/F25,"") -> 0.00047140626
...

Sheet FCFE
A1: Free Cash Flow to Equity (FCFE) — Wesfarmers Ltd (WES.AX)
A2: AUD $m | FY2026–FY2030 | All components formula-linked to pro-forma IS and BS
A4: SECTION 1 — FORMULA DEFINITION
A5: FCFE = E + NCC − ΔWCAP − FCInv + Net Borrowing + Δ Other NCL
A6: E = Net Income | IS row 79
A7: NCC = Depreciation (IS r30) + Amortisation (IS r29) — non-cash charges
A8: ΔWCAP = Change in Net Working Capital: (TCA−Cash) − (TCL−STDebt) | BS rows 35,20,113,104
A9: FCInv = Net Capex = PPE_t − PPE_{t−1} + Dep_t | BS row 41 + IS row 30
A10: Net Borrowing = Δ(LT Debt excl. leases + ST Debt) | BS rows 116, 104
A11: Δ Other NCL = Change in other non-current liabilities | BS row 120
A13: SECTION 2 — FCFE CALCULATION (FY2026–FY2030)
A14: Component | B14: 2026 | C14: 2027 | D14: 2028 | E14: 2029 | F14: 2030 | H14: Formula / Source Reference
A16: E — Net Income | B16: ='Income Statement'!K79 -> 3098 | C16: ='Income Statement'!L79 -> 3365 | D16: ='Income Statement'!M79 -> 3577 | E16: ='Income Statement'!N79 -> 3786 | F16: ='Income Statement'!O79 -> 3998 | H16: IS row 79: Net Income after Tax
A17: NCC — Depreciation | B17: ='Income Statement'!K30 -> 1604 | C17: ='Income Statement'!L30 -> 1671 | D17: ='Income Statement'!M30 -> 1747 | E17: ='Income Statement'!N30 -> 1830 | F17: ='Income Statement'!O30 -> 1919 | H17: IS row 30: Depreciation in Cost of Revenues
A18: NCC — Amortisation | B18: ='Income Statement'!K29 -> 186 | C18: ='Income Statement'!L29 -> 197 | D18: ='Income Statement'!M29 -> 209 | E18: ='Income Statement'!N29 -> 220 | F18: ='Income Statement'!O29 -> 232 | H18: IS row 29: Amortisation in Cost of Revenues
A19: NCC Total (Dep + Amort) | B19: =B17+B18 -> 1790 | C19: =C17+C18 -> 1868 | D19: =D17+D18 -> 1956 | E19: =E17+E18 -> 2050 | F19: =F17+F18 -> 2151 | H19: Sum of IS rows 30 and 29
A20: Less: ΔWCAP — Change in Net Working Capital | B20: =('Balance Sheet'!T35-'Balance Sheet'!T20-'Balance Sheet'!T113+'Balance Sheet'!T104)-('Balance Sheet'!G35-'Balance Sheet'!G20-'Balance Sheet'!G113+'Balance Sheet'!G104) -> -316 | C20: =('Balance Sheet'!U35-'Balance Sheet'!U20-'Balance Sheet'!U113+'Balance Sheet'!U104)-('Balance Sheet'!T35-'Balance Sheet'!T20-'Balance Sheet'!T113+'Balance Sheet'!T104) -> 110 | D20: =('Balance Sheet'!V35-'Balance Sheet'!V20-'Balance Sheet'!V113+'Balance Sheet'!V104)-('Balance Sheet'!U35-'Balance Sheet'!U20-'Balance Sheet'!U113+'Balance Sheet'!U104) -> 111 | E20: =('Balance Sheet'!W35-'Balance Sheet'!W20-'Balance Sheet'!W113+'Balance Sheet'!W104)-('Balance Sheet'!V35-'Balance Sheet'!V20-'Balance Sheet'!V113+'Balance Sheet'!V104) -> 111 | F20: =('Balance Sheet'!X35-'Balance Sheet'!X20-'Balance Sheet'!X113+'Balance Sheet'!X104)-('Balance Sheet'!W35-'Balance Sheet'!W20-'Balance Sheet'!W113+'Balance Sheet'!W104) -> 110 | H20: (TCA−Cash−TCL+STD)_t − prior year | BS rows 35,20,113,104
A21: NWC_t (supporting) | B21: ='Balance Sheet'!T35-'Balance Sheet'!T20-'Balance Sheet'!T113+'Balance Sheet'!T104 -> 1800 | C21: ='Balance Sheet'!U35-'Balance Sheet'!U20-'Balance Sheet'!U113+'Balance Sheet'!U104 -> 1910 | D21: ='Balance Sheet'!V35-'Balance Sheet'!V20-'Balance Sheet'!V113+'Balance Sheet'!V104 -> 2021 | E21: ='Balance Sheet'!W35-'Balance Sheet'!W20-'Balance Sheet'!W113+'Balance Sheet'!W104 -> 2132 | F21: ='Balance Sheet'!X35-'Balance Sheet'!X20-'Balance Sheet'!X113+'Balance Sheet'!X104 -> 2242 | H21: Net Working Capital each year (excl. cash and ST debt)
A22: Less: FCInv — Net Capital Expenditure | B22: ='Balance Sheet'!T41-'Balance Sheet'!G41+'Income Statement'!K30 -> 2064 | C22: ='Balance Sheet'!U41-'Balance Sheet'!T41+'Income Statement'!L30 -> 2191 | D22: ='Balance Sheet'!V41-'Balance Sheet'!U41+'Income Statement'!M30 -> 2319 | E22: ='Balance Sheet'!W41-'Balance Sheet'!V41+'Income Statement'!N30 -> 2446 | F22: ='Balance Sheet'!X41-'Balance Sheet'!W41+'Income Statement'!O30 -> 2573 | H22: PPE_t (BS r41) − PPE_{t-1} + Dep_t (IS r30) = Gross Capex
A23: Add: Net Borrowing — Δ(LT Debt + ST Debt) | B23: =('Balance Sheet'!T116+'Balance Sheet'!T104)-('Balance Sheet'!G116+'Balance Sheet'!G104) -> -25 | C23: =('Balance Sheet'!U116+'Balance Sheet'!U104)-('Balance Sheet'!T116+'Balance Sheet'!T104) -> 118 | D23: =('Balance Sheet'!V116+'Balance Sheet'!V104)-('Balance Sheet'!U116+'Balance Sheet'!U104) -> 117 | E23: =('Balance Sheet'!W116+'Balance Sheet'!W104)-('Balance Sheet'!V116+'Balance Sheet'!V104) -> 118 | F23: =('Balance Sheet'!X116+'Balance Sheet'!X104)-('Balance Sheet'!W116+'Balance Sheet'!W104) -> 118 | H23: (LTD+STD)_t − (LTD+STD)_{t-1} | BS rows 116, 104
A24: Add: Δ Other Non-Current Liabilities | B24: ='Balance Sheet'!T120-'Balance Sheet'!G120 -> 38 | C24: ='Balance Sheet'!U120-'Balance Sheet'!T120 -> 29 | D24: ='Balance Sheet'!V120-'Balance Sheet'!U120 -> 30 | E24: ='Balance Sheet'!W120-'Balance Sheet'!V120 -> 30 | F24: ='Balance Sheet'!X120-'Balance Sheet'!W120 -> 29 | H24: BS row 120: Other NCL Total vs prior year
A25: FCFE = E + NCC − ΔWCAP − FCInv + Net Borrowing + Δ Other NCL | B25: =B16+B19-B20-B22+B23+B24 -> 3153 | C25: =C16+C19-C20-C22+C23+C24 -> 3079 | D25: =D16+D19-D20-D22+D23+D24 -> 3250 | E25: =E16+E19-E20-E22+E23+E24 -> 3427 | F25: =F16+F19-F20-F22+F23+F24 -> 3613 | H25: e + ncc − ΔWCAP − FCInv + Net Borrowing + Δ Other NCL
A26: Duality of FCFE = Equity_{t-1} + Net Income − Equity_t | B26: ='Balance Sheet'!G142+'Income Statement'!K79-'Balance Sheet'!T142 -> 2731 | C26: ='Balance Sheet'!T142+'Income Statement'!L79-'Balance Sheet'!U142 -> 2967 | D26: ='Balance Sheet'!U142+'Income Statement'!M79-'Balance Sheet'!V142 -> 3153 | E26: ='Balance Sheet'!V142+'Income Statement'!N79-'Balance Sheet'!W142 -> 3338 | F26: ='Balance Sheet'!W142+'Income Statement'!O79-'Balance Sheet'!X142 -> 3525 | H26: BS Equity_{t-1} (r142) + NI (IS r79) − BS Equity_t | Model consistency check
A28: SECTION 3 — NOTES
A29: 1. All components are formula-linked to the pro-forma IS and BS — no values are hardcoded.
A30: 2. ΔWCAP excludes Cash (plug, BS row 20) and ST Debt (financing item, row 104) to isolate operating working capital.
A31: 3. FCInv = PPE_t − PPE_{t-1} + Dep_t. This equals gross capital expenditure (new investment before depreciation offset).
A32: 4. Net Borrowing uses interest-bearing debt only (LT excl. cap. leases r116 + ST debt r104). Cap. lease obligations excluded (non-cash AASB 16 entries).
A33: 5. Duality check: Equity_{t-1} + NI − Equity_t. Small residuals reflect OCI reserve movements (non-cash items bypassing P&L). This verifies RE accumulation is correct.
A34: 6. FCFE is positive in all forecast years, consistent with Wesfarmers strong earnings generation relative to reinvestment needs.

Sheet Balance Sheet
A1: Company Fundamentals - Balance Sheet
A2: Company Name | B2: Wesfarmers Ltd (WES.AX)
A3: Country of Exchange | B3: Australia
A4: Country of Headquarters | B4: Australia
A5: TRBC Industry Group | B5: Diversified Retail
A6: CF Template | B6: IND
A7: Consolidation Basis | B7: Consolidated
A8: Scaling | B8: Millions
A9: Period | B9: Annual
A10: Export Date | B10: 46164.123
A11: Statement Data | B11: 2025 | C11: 2024 | D11: 2023 | E11: 2022 | F11: 2021
A12: Period End Date | B12: 45838 | C12: 45473 | D12: 45107 | E12: 44742 | F12: 44377
A13: Statement Date | B13: 45838 | C13: 45473 | D13: 45107 | E13: 45107 | F13: 44377
A14: Standardized Currency | B14: AUD | C14: AUD | D14: AUD | E14: AUD | F14: AUD
A15: Template Type | B15: Industrial - Differentiated | C15: Industrial - Differentiated | D15: Industrial - Differentiated | E15: Industrial - Differentiated | F15: Industrial - Differentiated
A17: Balance Sheet - Standardized (Currency: Standardized)
A18: Field Name | B18: 30-06-2025 | C18: 30-06-2024 | D18: 30-06-2023 | E18: 30-06-2022 | F18: 30-06-2021 | G18: ADJ 30-06-2025 | H18: ADJ 30-06-2024 | I18: ADJ 30-06-2023 | J18: ADJ 30-06-2022 | K18: ADJ 30-06-2021 | L18: % Rev 2025adj | M18: % Rev 2024adj | N18: % Rev 2023adj | O18: % Rev 2022adj | P18: % Rev 2021adj | Q18: Avg % Rev | R18: Formula Description | S18: Excel Formula | T18: F2026 | U18: F2027 | V18: F2028 | W18: F2029 | X18: F2030
A19: Current Assets
A20: Cash & Short-Term Investments | B20: 638 | C20: 835 | D20: 673 | E20: 705 | F20: 3023 | G20: =B20 -> 638 | H20: =C20 -> 835 | I20: =D20 -> 673 | J20: =E20 -> 705 | K20: =F20 -> 3023 | L20: =IFERROR(G20/'Income Statement'!B25,"") -> 0.013960613 | M20: =IFERROR(H20/'Income Statement'!C25,"") -> 0.018896105 | N20: =IFERROR(I20/'Income Statement'!D25,"") -> 0.015453502 | O20: =IFERROR(J20/'Income Statement'!E25,"") -> 0.019137847 | P20: =IFERROR(K20/'Income Statement'!F25,"") -> 0.089066321 | Q20: =IFERROR(AVERAGE(L20:P20),"") -> 0.031302878 | R20: PLUG: Total L&E – Total NCA – Non-cash CA | S20: Total L&E - Total NCA - (Deriv+Rec+Inv+OtherCA) | T20: =ROUND(T146-T97-T22-T23-T29-T33,0) -> 2602 | U20: =ROUND(U146-U97-U22-U23-U29-U33,0) -> 2774 | V20: =ROUND(V146-V97-V22-V23-V29-V33,0) -> 2917 | W20: =ROUND(W146-W97-W22-W23-W29-W33,0) -> 3042 | X20: =ROUND(X146-X97-X22-X23-X29-X33,0) -> 3151
A21: Cash & Cash Equivalents | B21: 638 | C21: 835 | D21: 673 | E21: 705 | F21: 3023 | G21: =B21 -> 638 | H21: =C21 -> 835 | I21: =D21 -> 673 | J21: =E21 -> 705 | K21: =F21 -> 3023 | L21: =IFERROR(G21/'Income Statement'!B25,"") -> 0.013960613 | M21: =IFERROR(H21/'Income Statement'!C25,"") -> 0.018896105 | N21: =IFERROR(I21/'Income Statement'!D25,"") -> 0.015453502 | O21: =IFERROR(J21/'Income Statement'!E25,"") -> 0.019137847 | P21: =IFERROR(K21/'Income Statement'!F25,"") -> 0.089066321 | Q21: =IFERROR(AVERAGE(L21:P21),"") -> 0.031302878 | R21: 20 | S21: T20 (Cash Equivalents = Cash) | T21: =T20 -> 2602 | U21: =U20 -> 2774 | V21: =V20 -> 2917 | W21: =W20 -> 3042 | X21: =X20 -> 3151
A22: Derivative Financial Instruments - Hedging - Short-Term | B22: 31 | C22: 19 | D22: 116 | E22: 452 | F22: 152 | G22: =B22 -> 31 | H22: =C22 -> 19 | I22: =D22 -> 116 | J22: =E22 -> 452 | K22: =F22 -> 152 | L22: =IFERROR(G22/'Income Statement'!B25,"") -> 0.00067833698 | M22: =IFERROR(H22/'Income Statement'!C25,"") -> 0.00042997126 | N22: =IFERROR(I22/'Income Statement'!D25,"") -> 0.0026636051 | O22: =IFERROR(J22/'Income Statement'!E25,"") -> 0.012269939 | P22: =IFERROR(K22/'Income Statement'!F25,"") -> 0.0044783595 | Q22: =IFERROR(AVERAGE(L22:P22),"") -> 0.0041040423 | R22: Avg % of adjusted revenue | S22: ROUND(Q22*IS_rev,0) | T22: =ROUND(Q22*'Income Statement'!K25,0) -> 206 | U22: =ROUND(Q22*'Income Statement'!L25,0) -> 218 | V22: =ROUND(Q22*'Income Statement'!M25,0) -> 231 | W22: =ROUND(Q22*'Income Statement'!N25,0) -> 244 | X22: =ROUND(Q22*'Income Statement'!O25,0) -> 256
A23: Loans & Receivables - Net - Short-Term | B23: 2988 | C23: 2210 | D23: 2089 | E23: 2094 | F23: 1247 | G23: =B23 -> 2988 | H23: =C23 -> 2210 | I23: =D23 -> 2089 | J23: =E23 -> 2094 | K23: =F23 -> 1247 | L23: =IFERROR(G23/'Income Statement'!B25,"") -> 0.065382932 | M23: =IFERROR(H23/'Income Statement'!C25,"") -> 0.050012447 | N23: =IFERROR(I23/'Income Statement'!D25,"") -> 0.047967853 | O23: =IFERROR(J23/'Income Statement'!E25,"") -> 0.056843477 | P23: =IFERROR(K23/'Income Statement'!F25,"") -> 0.036740226 | Q23: =IFERROR(AVERAGE(L23:P23),"") -> 0.051389387 | R23: Avg % of adjusted revenue | S23: ROUND(Q23*IS_rev,0) | T23: =ROUND(Q23*'Income Statement'!K25,0) -> 2575 | U23: =ROUND(Q23*'Income Statement'!L25,0) -> 2733 | V23: =ROUND(Q23*'Income Statement'!M25,0) -> 2892 | W23: =ROUND(Q23*'Income Statement'!N25,0) -> 3051 | X23: =ROUND(Q23*'Income Statement'!O25,0) -> 3209
A24: Trade Accounts & Trade Notes Receivable - Net | B24: 2001 | C24: 1995 | D24: 1829 | E24: 1883 | F24: 1037 | G24: =B24 -> 2001 | H24: =C24 -> 1995 | I24: =D24 -> 1829 | J24: =E24 -> 1883 | K24: =F24 -> 1037 | L24: =IFERROR(G24/'Income Statement'!B25,"") -> 0.043785558 | M24: =IFERROR(H24/'Income Statement'!C25,"") -> 0.045146982 | N24: =IFERROR(I24/'Income Statement'!D25,"") -> 0.041997704 | O24: =IFERROR(J24/'Income Statement'!E25,"") -> 0.051115696 | P24: =IFERROR(K24/'Income Statement'!F25,"") -> 0.030553018 | Q24: =IFERROR(AVERAGE(L24:P24),"") -> 0.042519792 | R24: Avg % of adjusted revenue | S24: ROUND(Q24*IS_rev,0) | T24: =ROUND(Q24*'Income Statement'!K25,0) -> 2130 | U24: =ROUND(Q24*'Income Statement'!L25,0) -> 2262 | V24: =ROUND(Q24*'Income Statement'!M25,0) -> 2393 | W24: =ROUND(Q24*'Income Statement'!N25,0) -> 2524 | X24: =ROUND(Q24*'Income Statement'!O25,0) -> 2655
A25: Trade Accounts & Trade Notes Receivable - Gross | B25: 2052 | C25: 2055 | D25: 1892 | E25: 1938 | F25: 1070 | G25: =B25 -> 2052 | H25: =C25 -> 2055 | I25: =D25 -> 1892 | J25: =E25 -> 1938 | K25: =F25 -> 1070 | L25: =IFERROR(G25/'Income Statement'!B25,"") -> 0.044901532 | M25: =IFERROR(H25/'Income Statement'!C25,"") -> 0.046504786 | N25: =IFERROR(I25/'Income Statement'!D25,"") -> 0.043444317 | O25: =IFERROR(J25/'Income Statement'!E25,"") -> 0.052608719 | P25: =IFERROR(K25/'Income Statement'!F25,"") -> 0.031525294 | Q25: =IFERROR(AVERAGE(L25:P25),"") -> 0.04379693 | R25: Avg % of adjusted revenue | S25: ROUND(Q25*IS_rev,0) | T25: =ROUND(Q25*'Income Statement'!K25,0) -> 2194 | U25: =ROUND(Q25*'Income Statement'!L25,0) -> 2330 | V25: =ROUND(Q25*'Income Statement'!M25,0) -> 2465 | W25: =ROUND(Q25*'Income Statement'!N25,0) -> 2600 | X25: =ROUND(Q25*'Income Statement'!O25,0) -> 2735
A26: Provision - Trade Accounts & Trade Notes Receivable | B26: 51 | C26: 60 | D26: 63 | E26: 55 | F26: 33 | G26: =B26 -> 51 | H26: =C26 -> 60 | I26: =D26 -> 63 | J26: =E26 -> 55 | K26: =F26 -> 33 | L26: =IFERROR(G26/'Income Statement'!B25,"") -> 0.0011159737 | M26: =IFERROR(H26/'Income Statement'!C25,"") -> 0.001357804 | N26: =IFERROR(I26/'Income Statement'!D25,"") -> 0.0014466131 | O26: =IFERROR(J26/'Income Statement'!E25,"") -> 0.0014930235 | P26: =IFERROR(K26/'Income Statement'!F25,"") -> 0.00097227542 | Q26: =IFERROR(AVERAGE(L26:P26),"") -> 0.0012771379 | R26: Avg % of adjusted revenue | S26: ROUND(Q26*IS_rev,0) | T26: =ROUND(Q26*'Income Statement'!K25,0) -> 64 | U26: =ROUND(Q26*'Income Statement'!L25,0) -> 68 | V26: =ROUND(Q26*'Income Statement'!M25,0) -> 72 | W26: =ROUND(Q26*'Income Statement'!N25,0) -> 76 | X26: =ROUND(Q26*'Income Statement'!O25,0) -> 80
A27: Income Tax - Receivables - Short-Term | C27: 0 | D27: 43 | H27: =C27 -> 0 | I27: =D27 -> 43 | L27: =IFERROR(G27/'Income Statement'!B25,"") -> 0 | M27: =IFERROR(H27/'Income Statement'!C25,"") -> 0 | N27: =IFERROR(I27/'Income Statement'!D25,"") -> 0.00098737084 | O27: =IFERROR(J27/'Income Statement'!E25,"") -> 0 | P27: =IFERROR(K27/'Income Statement'!F25,"") -> 0 | Q27: =IFERROR(AVERAGE(L27:P27),"") -> 0.00019747417 | R27: Zero/nil in FY2025 – not forecast
A28: Receivables - Other - Total | B28: 987 | C28: 215 | D28: 217 | E28: 211 | F28: 210 | G28: =B28 -> 987 | H28: =C28 -> 215 | I28: =D28 -> 217 | J28: =E28 -> 211 | K28: =F28 -> 210 | L28: =IFERROR(G28/'Income Statement'!B25,"") -> 0.021597374 | M28: =IFERROR(H28/'Income Statement'!C25,"") -> 0.0048654643 | N28: =IFERROR(I28/'Income Statement'!D25,"") -> 0.0049827784 | O28: =IFERROR(J28/'Income Statement'!E25,"") -> 0.0057277811 | P28: =IFERROR(K28/'Income Statement'!F25,"") -> 0.0061872072 | Q28: =IFERROR(AVERAGE(L28:P28),"") -> 0.008672121 | R28: Avg % of adjusted revenue | S28: ROUND(Q28*IS_rev,0) | T28: =ROUND(Q28*'Income Statement'!K25,0) -> 435 | U28: =ROUND(Q28*'Income Statement'!L25,0) -> 461 | V28: =ROUND(Q28*'Income Statement'!M25,0) -> 488 | W28: =ROUND(Q28*'Income Statement'!N25,0) -> 515 | X28: =ROUND(Q28*'Income Statement'!O25,0) -> 542
A29: Inventories - Total | B29: 6038 | C29: 6102 | D29: 6039 | E29: 6084 | F29: 4502 | G29: =B29 -> 6038 | H29: =C29 -> 6102 | I29: =D29 -> 6039 | J29: =E29 -> 6084 | K29: =F29 -> 4502 | L29: =IFERROR(G29/'Income Statement'!B25,"") -> 0.13212254 | M29: =IFERROR(H29/'Income Statement'!C25,"") -> 0.13808866 | N29: =IFERROR(I29/'Income Statement'!D25,"") -> 0.1386682 | O29: =IFERROR(J29/'Income Statement'!E25,"") -> 0.16515555 | P29: =IFERROR(K29/'Income Statement'!F25,"") -> 0.13264194 | Q29: =IFERROR(AVERAGE(L29:P29),"") -> 0.14133538 | R29: Avg % of adjusted revenue | S29: ROUND(Q29*IS_rev,0) | T29: =ROUND(Q29*'Income Statement'!K25,0) -> 7081 | U29: =ROUND(Q29*'Income Statement'!L25,0) -> 7518 | V29: =ROUND(Q29*'Income Statement'!M25,0) -> 7954 | W29: =ROUND(Q29*'Income Statement'!N25,0) -> 8390 | X29: =ROUND(Q29*'Income Statement'!O25,0) -> 8827
A30: Inventories - Raw Materials | B30: 65 | C30: 57 | D30: 34 | E30: 28 | F30: 28 | G30: =B30 -> 65 | H30: =C30 -> 57 | I30: =D30 -> 34 | J30: =E30 -> 28 | K30: =F30 -> 28 | L30: =IFERROR(G30/'Income Statement'!B25,"") -> 0.0014223195 | M30: =IFERROR(H30/'Income Statement'!C25,"") -> 0.0012899138 | N30: =IFERROR(I30/'Income Statement'!D25,"") -> 0.00078071183 | O30: =IFERROR(J30/'Income Statement'!E25,"") -> 0.0007600847 | P30: =IFERROR(K30/'Income Statement'!F25,"") -> 0.00082496096 | Q30: =IFERROR(AVERAGE(L30:P30),"") -> 0.0010155981 | R30: Avg % of adjusted revenue | S30: ROUND(Q30*IS_rev,0) | T30: =ROUND(Q30*'Income Statement'!K25,0) -> 51 | U30: =ROUND(Q30*'Income Statement'!L25,0) -> 54 | V30: =ROUND(Q30*'Income Statement'!M25,0) -> 57 | W30: =ROUND(Q30*'Income Statement'!N25,0) -> 60 | X30: =ROUND(Q30*'Income Statement'!O25,0) -> 63
A31: Inventories - Finished Goods | B31: 5973 | C31: 6038 | D31: 5997 | E31: 6047 | F31: 4465 | G31: =B31 -> 5973 | H31: =C31 -> 6038 | I31: =D31 -> 5997 | J31: =E31 -> 6047 | K31: =F31 -> 4465 | L31: =IFERROR(G31/'Income Statement'!B25,"") -> 0.13070022 | M31: =IFERROR(H31/'Income Statement'!C25,"") -> 0.13664034 | N31: =IFERROR(I31/'Income Statement'!D25,"") -> 0.13770379 | O31: =IFERROR(J31/'Income Statement'!E25,"") -> 0.16415115 | P31: =IFERROR(K31/'Income Statement'!F25,"") -> 0.13155181 | Q31: =IFERROR(AVERAGE(L31:P31),"") -> 0.14014946 | R31: Avg % of adjusted revenue | S31: ROUND(Q31*IS_rev,0) | T31: =ROUND(Q31*'Income Statement'!K25,0) -> 7022 | U31: =ROUND(Q31*'Income Statement'!L25,0) -> 7455 | V31: =ROUND(Q31*'Income Statement'!M25,0) -> 7887 | W31: =ROUND(Q31*'Income Statement'!N25,0) -> 8320 | X31: =ROUND(Q31*'Income Statement'!O25,0) -> 8753
A32: Inventories - Other - Total | C32: 7 | D32: 8 | E32: 9 | F32: 9 | H32: =C32 -> 7 | I32: =D32 -> 8 | J32: =E32 -> 9 | K32: =F32 -> 9 | L32: =IFERROR(G32/'Income Statement'!B25,"") -> 0 | M32: =IFERROR(H32/'Income Statement'!C25,"") -> 0.00015841046 | N32: =IFERROR(I32/'Income Statement'!D25,"") -> 0.0001836969 | O32: =IFERROR(J32/'Income Statement'!E25,"") -> 0.00024431294 | P32: =IFERROR(K32/'Income Statement'!F25,"") -> 0.00026516602 | Q32: =IFERROR(AVERAGE(L32:P32),"") -> 0.00017031727 | R32: Zero/nil in FY2025 – not forecast
A33: Other Current Assets - Total | B33: 238 | C33: 248 | D33: 237 | E33: 264 | F33: 172 | G33: =B33 -> 238 | H33: =C33 -> 248 | I33: =D33 -> 237 | J33: =E33 -> 264 | K33: =F33 -> 172 | L33: =IFERROR(G33/'Income Statement'!B25,"") -> 0.0052078775 | M33: =IFERROR(H33/'Income Statement'!C25,"") -> 0.0056122564 | N33: =IFERROR(I33/'Income Statement'!D25,"") -> 0.0054420207 | O33: =IFERROR(J33/'Income Statement'!E25,"") -> 0.0071665128 | P33: =IFERROR(K33/'Income Statement'!F25,"") -> 0.0050676173 | Q33: =IFERROR(AVERAGE(L33:P33),"") -> 0.0056992569 | R33: Avg % of adjusted revenue | S33: ROUND(Q33*IS_rev,0) | T33: =ROUND(Q33*'Income Statement'!K25,0) -> 286 | U33: =ROUND(Q33*'Income Statement'!L25,0) -> 303 | V33: =ROUND(Q33*'Income Statement'!M25,0) -> 321 | W33: =ROUND(Q33*'Income Statement'!N25,0) -> 338 | X33: =ROUND(Q33*'Income Statement'!O25,0) -> 356
A34: Other Current Assets | B34: 238 | C34: 248 | D34: 237 | E34: 264 | F34: 172 | G34: =B34 -> 238 | H34: =C34 -> 248 | I34: =D34 -> 237 | J34: =E34 -> 264 | K34: =F34 -> 172 | L34: =IFERROR(G34/'Income Statement'!B25,"") -> 0.0052078775 | M34: =IFERROR(H34/'Income Statement'!C25,"") -> 0.0056122564 | N34: =IFERROR(I34/'Income Statement'!D25,"") -> 0.0054420207 | O34: =IFERROR(J34/'Income Statement'!E25,"") -> 0.0071665128 | P34: =IFERROR(K34/'Income Statement'!F25,"") -> 0.0050676173 | Q34: =IFERROR(AVERAGE(L34:P34),"") -> 0.0056992569 | R34: 33 | S34: T33 (sub-item = total) | T34: =T33 -> 286 | U34: =U33 -> 303 | V34: =V33 -> 321 | W34: =W33 -> 338 | X34: =X33 -> 356
A35: Total Current Assets | B35: =B20+B22+B23+B29+B33 -> 9933 | C35: =C20+C22+C23+C29+C33 -> 9414 | D35: =D20+D22+D23+D29+D33 -> 9154 | E35: =E20+E22+E23+E29+E33 -> 9599 | F35: =F20+F22+F23+F29+F33 -> 9096 | G35: =G20+G22+G23+G29+G33 -> 9933 | H35: =H20+H22+H23+H29+H33 -> 9414 | I35: =I20+I22+I23+I29+I33 -> 9154 | ... K35: =K20+K22+K23+K29+K33 -> 9096 | L35: =IFERROR(G35/'Income Statement'!B25,"") -> 0.2173523 | M35: =IFERROR(H35/'Income Statement'!C25,"") -> 0.21303944 | N35: =IFERROR(I35/'Income Statement'!D25,"") -> 0.21019518 | O35: =IFERROR(J35/'Income Statement'!E25,"") -> 0.26057332 | P35: =IFERROR(K35/'Income Statement'!F25,"") -> 0.26799446 | Q35: =IFERROR(AVERAGE(L35:P35),"") -> 0.23383094 | R35: SUM: Cash + Deriv.Hedging + Loans&Rec + Inventories + OtherCA | S35: T20+T22+T23+T29+T33 | T35: =T20+T22+T23+T29+T33 -> 12750 | U35: =U20+U22+U23+U29+U33 -> 13546 | V35: =V20+V22+V23+V29+V33 -> 14315 | W35: =W20+W22+W23+W29+W33 -> 15065 | X35: =X20+X22+X23+X29+X33 -> 15799
A36: Non-Current Assets
A37: Investments - Long-Term | D37: 15 | E37: 677 | F37: 1124 | I37: =D37 -> 15 | J37: =E37 -> 677 | K37: =F37 -> 1124 | L37: =IFERROR(G37/'Income Statement'!B25,"") -> 0 | M37: =IFERROR(H37/'Income Statement'!C25,"") -> 0 | N37: =IFERROR(I37/'Income Statement'!D25,"") -> 0.00034443169 | O37: =IFERROR(J37/'Income Statement'!E25,"") -> 0.018377762 | P37: =IFERROR(K37/'Income Statement'!F25,"") -> 0.03311629 | Q37: =IFERROR(AVERAGE(L37:P37),"") -> 0.010367697 | R37: Zero/nil in FY2025 – not forecast
A38: Investments - Available for Sale/Held to Maturity - Long-Term | D38: 15 | E38: 677 | F38: 1124 | I38: =D38 -> 15 | J38: =E38 -> 677 | K38: =F38 -> 1124 | L38: =IFERROR(G38/'Income Statement'!B25,"") -> 0 | M38: =IFERROR(H38/'Income Statement'!C25,"") -> 0 | N38: =IFERROR(I38/'Income Statement'!D25,"") -> 0.00034443169 | O38: =IFERROR(J38/'Income Statement'!E25,"") -> 0.018377762 | P38: =IFERROR(K38/'Income Statement'!F25,"") -> 0.03311629 | Q38: =IFERROR(AVERAGE(L38:P38),"") -> 0.010367697 | R38: 37 | S38: T37 (sub-item) | T38: =T37 -> 0 | U38: =U37 -> 0 | V38: =V37 -> 0 | W38: =W37 -> 0 | X38: =X37 -> 0
A39: Investments in Associates, Joint Ventures and Unconsolidated Subsidiaries | B39: 1113 | C39: 938 | D39: 943 | E39: 934 | F39: 775 | G39: =B39 -> 1113 | H39: =C39 -> 938 | I39: =D39 -> 943 | J39: =E39 -> 934 | K39: =F39 -> 775 | L39: =IFERROR(G39/'Income Statement'!B25,"") -> 0.024354486 | M39: =IFERROR(H39/'Income Statement'!C25,"") -> 0.021227002 | N39: =IFERROR(I39/'Income Statement'!D25,"") -> 0.021653272 | O39: =IFERROR(J39/'Income Statement'!E25,"") -> 0.025354254 | P39: =IFERROR(K39/'Income Statement'!F25,"") -> 0.022833741 | Q39: =IFERROR(AVERAGE(L39:P39),"") -> 0.023084551 | R39: Avg % of adjusted revenue | S39: ROUND(Q39*IS_rev,0) | T39: =ROUND(Q39*'Income Statement'!K25,0) -> 1157 | U39: =ROUND(Q39*'Income Statement'!L25,0) -> 1228 | V39: =ROUND(Q39*'Income Statement'!M25,0) -> 1299 | W39: =ROUND(Q39*'Income Statement'!N25,0) -> 1370 | X39: =ROUND(Q39*'Income Statement'!O25,0) -> 1442
A40: Derivative Financial Instruments - Hedging - Long-Term | B40: 96 | C40: 22 | D40: 27 | E40: 8 | F40: 282 | G40: =B40 -> 96 | H40: =C40 -> 22 | I40: =D40 -> 27 | J40: =E40 -> 8 | K40: =F40 -> 282 | L40: =IFERROR(G40/'Income Statement'!B25,"") -> 0.0021006565 | M40: =IFERROR(H40/'Income Statement'!C25,"") -> 0.00049786146 | N40: =IFERROR(I40/'Income Statement'!D25,"") -> 0.00061997704 | O40: =IFERROR(J40/'Income Statement'!E25,"") -> 0.00021716706 | P40: =IFERROR(K40/'Income Statement'!F25,"") -> 0.0083085354 | Q40: =IFERROR(AVERAGE(L40:P40),"") -> 0.0023488395 | R40: Avg % of adjusted revenue | S40: ROUND(Q40*IS_rev,0) | T40: =ROUND(Q40*'Income Statement'!K25,0) -> 118 | U40: =ROUND(Q40*'Income Statement'!L25,0) -> 125 | V40: =ROUND(Q40*'Income Statement'!M25,0) -> 132 | W40: =ROUND(Q40*'Income Statement'!N25,0) -> 139 | X40: =ROUND(Q40*'Income Statement'!O25,0) -> 147
A41: Property, Plant & Equipment - Net - Total | B41: 11040 | C41: 11150 | D41: 11041 | E41: 10764 | F41: 10397 | G41: =B41 -> 11040 | H41: =C41 -> 11150 | I41: =D41 -> 11041 | J41: =E41 -> 10764 | K41: =F41 -> 10397 | L41: =IFERROR(G41/'Income Statement'!B25,"") -> 0.24157549 | M41: =IFERROR(H41/'Income Statement'!C25,"") -> 0.25232524 | N41: =IFERROR(I41/'Income Statement'!D25,"") -> 0.25352468 | O41: =IFERROR(J41/'Income Statement'!E25,"") -> 0.29219827 | P41: =IFERROR(K41/'Income Statement'!F25,"") -> 0.30632568 | Q41: =IFERROR(AVERAGE(L41:P41),"") -> 0.26918987 | R41: Prior PPE + Capex (4.12% of rev) – Depreciation (IS row 30) | S41: prior_PPE + 0.0412×IS_rev – IS_Dep_row30 | T41: =ROUND(G41+0.0412*'Income Statement'!K25-'Income Statement'!K30,0) -> 11500 | U41: =ROUND(T41+0.0412*'Income Statement'!L25-'Income Statement'!L30,0) -> 12020 | V41: =ROUND(U41+0.0412*'Income Statement'!M25-'Income Statement'!M30,0) -> 12592 | W41: =ROUND(V41+0.0412*'Income Statement'!N25-'Income Statement'!N30,0) -> 13208 | X41: =ROUND(W41+0.0412*'Income Statement'!O25-'Income Statement'!O30,0) -> 13862
...

Sheet Dividend Analysis
A2: Year | B2: Earnings/Net Income | C2: Retained Earnings(t-1) | D2: Retained Earnings(t) | E2: Dividend Distribution | F2: Dividend Payout Ratio | G2: Retention Ratio
A3: 2021 | B3: ='Income Statement'!F79 -> 2380 | C3: -10085 | D3: ='Balance Sheet'!K137 -> -9724 | E3: =B3+C3-D3 -> 2019 | F3: =E3/B3 -> 0.84831933 | G3: =1-F3 -> 0.15168067
A4: 2022 | B4: ='Income Statement'!E79 -> 2352 | C4: ='Balance Sheet'!K137 -> -9724 | D4: ='Balance Sheet'!J137 -> -9637 | E4: =B4+C4-D4 -> 2265 | F4: =E4/B4 -> 0.9630102 | G4: =1-F4 -> 0.036989796
A5: 2023 | B5: ='Income Statement'!D79 -> 2465 | C5: ='Balance Sheet'!J137 -> -9637 | D5: ='Balance Sheet'!I137 -> -9369 | E5: =B5+C5-D5 -> 2197 | F5: =E5/B5 -> 0.89127789 | G5: =1-F5 -> 0.10872211
A6: 2024 | B6: ='Income Statement'!C79 -> 2557 | C6: ='Balance Sheet'!I137 -> -9369 | D6: ='Balance Sheet'!H137 -> -9267 | E6: =B6+C6-D6 -> 2455 | F6: =E6/B6 -> 0.9601095 | G6: =1-F6 -> 0.039890497
A7: 2025 | B7: ='Income Statement'!B79 -> 2926 | C7: ='Balance Sheet'!H137 -> -9267 | D7: ='Balance Sheet'!G137 -> -8522 | E7: =B7+C7-D7 -> 2181 | F7: =E7/B7 -> 0.74538619 | G7: =1-F7 -> 0.25461381
E8: Average | F8: =AVERAGE(F3:F7) -> 0.88162062 | G8: =1-F8 -> 0.11837938
A10: 2026 | B10: ='Income Statement'!K79 -> 3098 | C10: ='Balance Sheet'!G137 -> -8522 | D10: =B10+C10-E10 -> -8155.2607 | E10: =B10*F10 -> 2731.2607 | F10: =$F$8 -> 0.88162062 | G10: =1-F10 -> 0.11837938
A11: 2027 | B11: ='Income Statement'!L79 -> 3365 | C11: ='Balance Sheet'!T137 -> -8155 | D11: =B11+C11-E11 -> -7756.6534 | E11: =B11*F11 -> 2966.6534 | F11: =$F$8 -> 0.88162062 | G11: =1-F11 -> 0.11837938
A12: 2028 | B12: ='Income Statement'!M79 -> 3577 | C12: ='Balance Sheet'!U137 -> -7757 | D12: =B12+C12-E12 -> -7333.557 | E12: =B12*F12 -> 3153.557 | F12: =$F$8 -> 0.88162062 | G12: =1-F12 -> 0.11837938
A13: 2029 | B13: ='Income Statement'!N79 -> 3786 | C13: ='Balance Sheet'!V137 -> -7333 | D13: =B13+C13-E13 -> -6884.8157 | E13: =B13*F13 -> 3337.8157 | F13: =$F$8 -> 0.88162062 | G13: =1-F13 -> 0.11837938
A14: 2030 | B14: ='Income Statement'!O79 -> 3998 | C14: ='Balance Sheet'!W137 -> -6885 | D14: =B14+C14-E14 -> -6411.7193 | E14: =B14*F14 -> 3524.7193 | F14: =$F$8 -> 0.88162062 | G14: =1-F14 -> 0.11837938
B17: Note: The dividend payout ratio is calculated as total dividends paid divided by adjusted NPAT each year. Payout ratios are capped at a maximum of 100% and floored at a minimum of 0% per assignment instructions. The average historical payout ratio of 88.16% is applied uniformly to all forecast years 2026–2030.

Sheet Revenue Forecast
A1: Year | B1: Nominal Operating Revenue | C1: CPI | D1: Real Operating Revenue | E1: Real GDP (in $ millions) | F1: Population Growth Rate (%)
A2: 1995 | B2: 2512.7 | C2: 66 | D2: =(B2*$C$32)/C2 -> 5482.2545 | E2: 281218 | F2: 1.11
A3: 1996 | B3: 2513.03 | C3: 67 | D3: =(B3*$C$32)/C3 -> 5401.1391 | E3: 292390 | F3: 1.21 | H3: SUMMARY OUTPUT
A4: 1997 | B4: 2709.52 | C4: 66.8 | D4: =(B4*$C$32)/C4 -> 5840.8814 | E4: 306170 | F4: 1.08
A5: 1998 | B5: 2822.77 | C5: 67.8 | D5: =(B5*$C$32)/C5 -> 5995.2637 | E5: 320472 | F5: 1 | H5: Regression Statistics
A6: 1999 | B6: 3119.46 | C6: 69.1 | D6: =(B6*$C$32)/C6 -> 6500.756 | E6: 334691 | F6: 1.09 | H6: Multiple R | I6: 0.65626381
A7: 2000 | B7: 3480.16 | C7: 73.1 | D7: =(B7*$C$32)/C7 -> 6855.5819 | E7: 345063 | F7: 1.14 | H7: R Square | I7: 0.43068219
A8: 2001 | B8: 4388.65 | C8: 75.4 | D8: =(B8*$C$32)/C8 -> 8381.5066 | E8: 354037 | F8: 1.28 | H8: Adjusted R Square | I8: 0.39001663
A9: 2002 | B9: 7385.66 | C9: 77.6 | D9: =(B9*$C$32)/C9 -> 13705.348 | E9: 368762 | F9: 1.14 | H9: Standard Error | I9: 23599.078
A10: 2003 | B10: 7753.37 | C10: 79.5 | D10: =(B10*$C$32)/C10 -> 14043.84 | E10: 379882 | F10: 1.15 | H10: Observations | I10: 31
A11: 2004 | B11: 8407.49 | C11: 81.5 | D11: =(B11*$C$32)/C11 -> 14854.952 | E11: 395507 | F11: 1.07
A12: 2005 | B12: 8158.63 | C12: 83.8 | D12: =(B12*$C$32)/C12 -> 14019.603 | E12: 407488 | F12: 1.22 | H12: ANOVA
A13: 2006 | B13: 8858.8 | C13: 86.6 | D13: =(B13*$C$32)/C13 -> 14730.568 | E13: 418165 | F13: 1.35 | I13: df | J13: SS | K13: MS | L13: F | M13: Significance F
A14: 2007 | B14: 9754 | C14: 89.1 | D14: =(B14*$C$32)/C14 -> 15764.04 | E14: 436310 | F14: 1.82 | H14: Regression | I14: 2 | J14: 1.1796421e+10 | K14: 5.8982103e+09 | L14: 10.590834 | M14: 0.00037580866
A15: 2008 | B15: 33584 | C15: 92.4 | D15: =(B15*$C$32)/C15 -> 52338.701 | E15: 447630 | F15: 2 | H15: Residual | I15: 28 | J15: 1.5593662e+10 | K15: 5.5691649e+08
A16: 2009 | B16: 50982 | C16: 94.3 | D16: =(B16*$C$32)/C16 -> 77851.622 | E16: 456424 | F16: 2.06 | H16: Total | I16: 30 | J16: 2.7390082e+10
A17: 2010 | B17: 51827 | C17: 96.9 | D17: =(B17*$C$32)/C17 -> 77018.452 | E17: 467465 | F17: 1.56
A18: 2011 | B18: 54875 | C18: 99.8 | D18: =(B18*$C$32)/C18 -> 79178.357 | E18: 480487 | F18: 1.39 | I18: Coefficients | J18: Standard Error | K18: t Stat | L18: P-value | M18: Lower 95% | N18: Upper 95% | O18: Lower 95.0% | P18: Upper 95.0%
A19: 2012 | B19: 58080 | C19: 102 | D19: =(B19*$C$32)/C19 -> 81995.294 | E19: 498692 | F19: 1.75 | H19: Intercept | I19: -49767.912 | J19: 19958.437 | K19: -2.4935776 | L19: 0.018826301 | M19: -90650.918 | N19: -8884.9063 | O19: -90650.918 | P19: -8884.9063
A20: 2013 | B20: 57749 | C20: 104.8 | D20: =(B20*$C$32)/C20 -> 79349.771 | E20: 509758 | F20: 1.72 | H20: Real GDP (in $ millions) | I20: 0.12763112 | J20: 0.039992641 | K20: 3.1913651 | L20: 0.0034803171 | M20: 0.045709909 | N20: 0.20955233 | O20: 0.045709909 | P20: 0.20955233
A21: 2014 | B21: 60181 | C21: 106.6 | D21: =(B21*$C$32)/C21 -> 81295.159 | E21: 522882 | F21: 1.49 | H21: Population Growth Rate (%) | I21: 20807.11 | J21: 11055.7 | K21: 1.8820255 | L21: 0.070264748 | M21: -1839.4659 | N21: 43453.685 | O21: -1839.4659 | P21: 43453.685
A22: 2015 | B22: 62447 | C22: 108.4 | D22: =(B22*$C$32)/C22 -> 82955.424 | E22: 535118 | F22: 1.44
A23: 2016 | B23: 65981 | C23: 110 | D23: =(B23*$C$32)/C23 -> 86375.127 | E23: 549536 | F23: 1.56
A24: 2017 | B24: 64913 | C24: 112.1 | D24: =(B24*$C$32)/C24 -> 83385.12 | E24: 562614 | F24: 1.65
A25: 2018 | B25: 26763 | C25: 114.1 | D25: =(B25*$C$32)/C25 -> 33776.266 | E25: 578318 | F25: 1.5
A26: 2019 | B26: 27920 | C26: 116.2 | D26: =(B26*$C$32)/C26 -> 34599.656 | E26: 589512 | F26: 1.48
A27: 2020 | B27: 30846 | C27: 117.2 | D27: =(B27*$C$32)/C27 -> 37899.522 | E27: 577992 | F27: 1.23
A28: 2021 | B28: 33941 | C28: 121.3 | D28: =(B28*$C$32)/C28 -> 40292.696 | E28: 609318 | F28: 0.14
A29: 2022 | B29: 36838 | C29: 130.8 | D29: =(B29*$C$32)/C29 -> 40555.596 | E29: 634519 | F29: 1.27
A30: 2023 | B30: 43550 | C30: 136.1 | D30: =(B30*$C$32)/C30 -> 46077.884 | E30: 647548 | F30: 2.42
A31: 2024 | B31: 44189 | C31: 139.4 | D31: =(B31*$C$32)/C31 -> 45647.174 | E31: 654212 | F31: 2.05
A32: 2025 | B32: 45700 | C32: 144 | D32: =(B32*$C$32)/C32 -> 45700 | E32: 656388 | F32: 1.6
H34: Macroeconomic Assumptions
H35: Year | I35: Growth % | J35: Population Growth Rate (%)
A36: Year | B36: Real GDP (in $ millions) | C36: Population Growth Rate (%) | D36: Real Operating Revenue | E36: Inflation (%) | F36: Nominal Operating Revenue | H36: 2021 | I36: 5.42 | J36: 0.14
A37: 2026 | B37: =E32*I43 -> 673414.7 | C37: =J$41 -> 1.496 | D37: =I19+(I20*B37)+(I21*C37) -> 67308.198 | E37: 2.5 | F37: =D37*E43 -> 68990.903 | H37: 2022 | I37: 4.14 | J37: 1.27
A38: 2027 | B38: =B37*I43 -> 690883.08 | C38: =J$41 -> 1.496 | D38: =I19+(I20*B38)+(I21*C38) -> 69537.706 | E38: 2.5 | F38: =D38*E43 -> 71276.149 | H38: 2023 | I38: 2.05 | J38: 2.42
A39: 2028 | B39: =B38*I43 -> 708804.59 | C39: =J$41 -> 1.496 | D39: =I19+(I20*B39)+(I21*C39) -> 71825.048 | E39: 2.5 | F39: =D39*E43 -> 73620.674 | H39: 2024 | I39: 1.03 | J39: 2.05
A40: 2029 | B40: =B39*I43 -> 727190.98 | C40: =J$41 -> 1.496 | D40: =I19+(I20*B40)+(I21*C40) -> 74171.724 | E40: 2.5 | F40: =D40*E43 -> 76026.017 | H40: 2025 | I40: 0.33 | J40: 1.6
A41: 2030 | B41: =B40*I43 -> 746054.31 | C41: =J$41 -> 1.496 | D41: =I19+(I20*B41)+(I21*C41) -> 76579.272 | E41: 2.5 | F41: =D41*E43 -> 78493.754 | H41: Average | I41: =AVERAGE(I36:I40) -> 2.594 | J41: =AVERAGE(J36:J40) -> 1.496
...

Sheet FCFE & FCFF
A1: Valuation of FCFE | B1: 2026 | C1: 2027 | D1: 2028 | E1: 2029 | F1: 2030 | H1: Valuation of FCFE | I1: 2026 | J1: 2027 | K1: 2028 | L1: 2029 | M1: 2030
A2: Earnings | B2: ='Income Statement'!K79 -> 3098 | C2: ='Income Statement'!L79 -> 3365 | D2: ='Income Statement'!M79 -> 3577 | E2: ='Income Statement'!N79 -> 3786 | F2: ='Income Statement'!O79 -> 3998 | H2: FCFE | I2: =B8 -> 3153 | J2: =C8 -> 3079 | K2: =D8 -> 3250 | L2: =E8 -> 3427 | M2: =F8 -> 3613
A3: NCC | B3: ='Income Statement'!K29+'Income Statement'!K30 -> 1790 | C3: ='Income Statement'!L29+'Income Statement'!L30 -> 1868 | D3: ='Income Statement'!M29+'Income Statement'!M30 -> 1956 | E3: ='Income Statement'!N29+'Income Statement'!N30 -> 2050 | F3: ='Income Statement'!O29+'Income Statement'!O30 -> 2151 | H3: D/E | I3: =('Balance Sheet'!T116+'Balance Sheet'!T104)/'Balance Sheet'!T142 -> 1.0746735 | J3: =('Balance Sheet'!U116+'Balance Sheet'!U104)/'Balance Sheet'!U142 -> 1.0215938 | K3: =('Balance Sheet'!V116+'Balance Sheet'!V104)/'Balance Sheet'!V142 -> 0.97108164 | L3: =('Balance Sheet'!W116+'Balance Sheet'!W104)/'Balance Sheet'!W142 -> 0.92381094 | M3: =('Balance Sheet'!X116+'Balance Sheet'!X104)/'Balance Sheet'!X142 -> 0.87938719
A4: WCInv | B4: ='Balance Sheet'!T35-'Balance Sheet'!T20-'Balance Sheet'!T113+'Balance Sheet'!T104-(('Balance Sheet'!G35-'Balance Sheet'!G20-'Balance Sheet'!G113+'Balance Sheet'!G104)) -> -316 | C4: ='Balance Sheet'!U35-'Balance Sheet'!U20-'Balance Sheet'!U113+'Balance Sheet'!U104-(('Balance Sheet'!T35-'Balance Sheet'!T20-'Balance Sheet'!T113+'Balance Sheet'!T104)) -> 110 | D4: ='Balance Sheet'!V35-'Balance Sheet'!V20-'Balance Sheet'!V113+'Balance Sheet'!V104-(('Balance Sheet'!U35-'Balance Sheet'!U20-'Balance Sheet'!U113+'Balance Sheet'!U104)) -> 111 | E4: ='Balance Sheet'!W35-'Balance Sheet'!W20-'Balance Sheet'!W113+'Balance Sheet'!W104-(('Balance Sheet'!V35-'Balance Sheet'!V20-'Balance Sheet'!V113+'Balance Sheet'!V104)) -> 111 | F4: ='Balance Sheet'!X35-'Balance Sheet'!X20-'Balance Sheet'!X113+'Balance Sheet'!X104-(('Balance Sheet'!W35-'Balance Sheet'!W20-'Balance Sheet'!W113+'Balance Sheet'!W104)) -> 110 | H4: Unlevered beta | I4: 0.5007 | J4: 0.5007 | K4: 0.5007 | L4: 0.5007 | M4: 0.5007
A5: FCInv | B5: ='Balance Sheet'!T41-'Balance Sheet'!G41+'Income Statement'!K30 -> 2064 | C5: ='Balance Sheet'!U41-'Balance Sheet'!T41+'Income Statement'!L30 -> 2191 | D5: ='Balance Sheet'!V41-'Balance Sheet'!U41+'Income Statement'!M30 -> 2319 | E5: ='Balance Sheet'!W41-'Balance Sheet'!V41+'Income Statement'!N30 -> 2446 | F5: ='Balance Sheet'!X41-'Balance Sheet'!W41+'Income Statement'!O30 -> 2573 | H5: Levered Beta | I5: =0.5007*(1+0.7103*('Balance Sheet'!T116+'Balance Sheet'!T104)/'Balance Sheet'!T142) -> 0.88290464 | J5: =0.5007*(1+0.7103*('Balance Sheet'!U116+'Balance Sheet'!U104)/'Balance Sheet'!U142) -> 0.864027 | K5: =0.5007*(1+0.7103*('Balance Sheet'!V116+'Balance Sheet'!V104)/'Balance Sheet'!V142) -> 0.84606248 | L5: =0.5007*(1+0.7103*('Balance Sheet'!W116+'Balance Sheet'!W104)/'Balance Sheet'!W142) -> 0.82925078 | M5: =0.5007*(1+0.7103*('Balance Sheet'!X116+'Balance Sheet'!X104)/'Balance Sheet'!X142) -> 0.8134516
A6: Net Borrowing | B6: =('Balance Sheet'!T116+'Balance Sheet'!T104)-('Balance Sheet'!G116+'Balance Sheet'!G104) -> -25 | C6: =('Balance Sheet'!U116+'Balance Sheet'!U104)-('Balance Sheet'!T116+'Balance Sheet'!T104) -> 118 | D6: =('Balance Sheet'!V116+'Balance Sheet'!V104)-('Balance Sheet'!U116+'Balance Sheet'!U104) -> 117 | E6: =('Balance Sheet'!W116+'Balance Sheet'!W104)-('Balance Sheet'!V116+'Balance Sheet'!V104) -> 118 | F6: =('Balance Sheet'!X116+'Balance Sheet'!X104)-('Balance Sheet'!W116+'Balance Sheet'!W104) -> 118 | H6: Risk-free rate | I6: 0.02709 | J6: 0.02709 | K6: 0.02709 | L6: 0.02709 | M6: 0.02709
A7: Other NCL | B7: ='Balance Sheet'!T120-'Balance Sheet'!G120 -> 38 | C7: ='Balance Sheet'!U120-'Balance Sheet'!T120 -> 29 | D7: ='Balance Sheet'!V120-'Balance Sheet'!U120 -> 30 | E7: ='Balance Sheet'!W120-'Balance Sheet'!V120 -> 30 | F7: ='Balance Sheet'!X120-'Balance Sheet'!W120 -> 29 | H7: Risk premium | I7: 0.07733 | J7: 0.07733 | K7: 0.07733 | L7: 0.07733 | M7: 0.07733
A8: FCFE | B8: =B2+B3-B4-B5+B6+B7 -> 3153 | C8: =C2+C3-C4-C5+C6+C7 -> 3079 | D8: =D2+D3-D4-D5+D6+D7 -> 3250 | E8: =E2+E3-E4-E5+E6+E7 -> 3427 | F8: =F2+F3-F4-F5+F6+F7 -> 3613 | H8: Cost of equity | I8: =I6+I5*I7 -> 0.095365016 | J8: =J6+J5*J7 -> 0.093905208 | K8: =K6+K5*K7 -> 0.092516011 | L8: =L6+L5*L7 -> 0.091215963 | M8: =M6+M5*M7 -> 0.089994212
A9: Duality of FCFE | B9: ='Balance Sheet'!G142+'Income Statement'!K79-'Balance Sheet'!T142 -> 2731 | C9: ='Balance Sheet'!T142+'Income Statement'!L79-'Balance Sheet'!U142 -> 2967 | D9: ='Balance Sheet'!U142+'Income Statement'!M79-'Balance Sheet'!V142 -> 3153 | E9: ='Balance Sheet'!V142+'Income Statement'!N79-'Balance Sheet'!W142 -> 3338 | F9: ='Balance Sheet'!W142+'Income Statement'!O79-'Balance Sheet'!X142 -> 3525 | H9: Present value | I9: =I2/(1+I8)^1 -> 2878.4925 | J9: =J2/(1+J8)^2 -> 2573.0623 | K9: =K2/(1+K8)^3 -> 2492.2978 | L9: =L2/(1+L8)^4 -> 2416.97 | M9: =M2/(1+M8)^5 -> 2348.2644
H10: Long-term growth rate | I10: 0.0125 | J10: 0.0125 | K10: 0.0125 | L10: 0.0125 | M10: 0.0125
H11: Terminal value | N11: =M2*(1+M10)/(M8-M10) -> 47205.622
A12: Valuation of FCFF | B12: 2026 | C12: 2027 | D12: 2028 | E12: 2029 | F12: 2030 | H12: PVTV | N12: =N11/(1+M8)^5 -> 30681.23
A13: Earnings | B13: ='Income Statement'!K79 -> 3098 | C13: ='Income Statement'!L79 -> 3365 | D13: ='Income Statement'!M79 -> 3577 | E13: ='Income Statement'!N79 -> 3786 | F13: ='Income Statement'!O79 -> 3998 | H13: Total Present Value of Equity | N13: =SUM(I9:M9)+N12 -> 43390.317
A14: NCC | B14: ='Income Statement'!K29+'Income Statement'!K30 -> 1790 | C14: ='Income Statement'!L29+'Income Statement'!L30 -> 1868 | D14: ='Income Statement'!M29+'Income Statement'!M30 -> 1956 | E14: ='Income Statement'!N29+'Income Statement'!N30 -> 2050 | F14: ='Income Statement'!O29+'Income Statement'!O30 -> 2151 | H14: Number of Shares (m) | N14: 1140
A15: WCInv | B15: ='Balance Sheet'!T35-'Balance Sheet'!T20-'Balance Sheet'!T113+'Balance Sheet'!T104-(('Balance Sheet'!G35-'Balance Sheet'!G20-'Balance Sheet'!G113+'Balance Sheet'!G104)) -> -316 | C15: ='Balance Sheet'!U35-'Balance Sheet'!U20-'Balance Sheet'!U113+'Balance Sheet'!U104-(('Balance Sheet'!T35-'Balance Sheet'!T20-'Balance Sheet'!T113+'Balance Sheet'!T104)) -> 110 | D15: ='Balance Sheet'!V35-'Balance Sheet'!V20-'Balance Sheet'!V113+'Balance Sheet'!V104-(('Balance Sheet'!U35-'Balance Sheet'!U20-'Balance Sheet'!U113+'Balance Sheet'!U104)) -> 111 | E15: ='Balance Sheet'!W35-'Balance Sheet'!W20-'Balance Sheet'!W113+'Balance Sheet'!W104-(('Balance Sheet'!V35-'Balance Sheet'!V20-'Balance Sheet'!V113+'Balance Sheet'!V104)) -> 111 | F15: ='Balance Sheet'!X35-'Balance Sheet'!X20-'Balance Sheet'!X113+'Balance Sheet'!X104-(('Balance Sheet'!W35-'Balance Sheet'!W20-'Balance Sheet'!W113+'Balance Sheet'!W104)) -> 110 | H15: Price per Share ($) | N15: =N13/N14 -> 38.061682
A16: FCInv | B16: ='Balance Sheet'!T41-'Balance Sheet'!G41+'Income Statement'!K30 -> 2064 | C16: ='Balance Sheet'!U41-'Balance Sheet'!T41+'Income Statement'!L30 -> 2191 | D16: ='Balance Sheet'!V41-'Balance Sheet'!U41+'Income Statement'!M30 -> 2319 | E16: ='Balance Sheet'!W41-'Balance Sheet'!V41+'Income Statement'!N30 -> 2446 | F16: ='Balance Sheet'!X41-'Balance Sheet'!W41+'Income Statement'!O30 -> 2573 | H16: Market price as at 01/07/25 | N16: 73.47
A17: Interest (1-T) | B17: =ROUND('Income Statement'!K50*0.7103,0) -> 329 | C17: =ROUND('Income Statement'!L50*0.7103,0) -> 274 | D17: =ROUND('Income Statement'!M50*0.7103,0) -> 274 | E17: =ROUND('Income Statement'!N50*0.7103,0) -> 274 | F17: =ROUND('Income Statement'!O50*0.7103,0) -> 274 | H17: Recommendation buy/ sell/ hold | N17: =IF(N15>N16,"BUY","SELL") -> SELL
A18: Other NCL | B18: ='Balance Sheet'!T120-'Balance Sheet'!G120 -> 38 | C18: ='Balance Sheet'!U120-'Balance Sheet'!T120 -> 29 | D18: ='Balance Sheet'!V120-'Balance Sheet'!U120 -> 30 | E18: ='Balance Sheet'!W120-'Balance Sheet'!V120 -> 30 | F18: ='Balance Sheet'!X120-'Balance Sheet'!W120 -> 29 | H18: Cost of equity | I18: =I8 -> 0.095365016 | J18: =J8 -> 0.093905208 | K18: =K8 -> 0.092516011 | L18: =L8 -> 0.091215963 | M18: =M8 -> 0.089994212
A19: FCFF | B19: =B13+B14-B15-B16+B17+B18 -> 3507 | C19: =C13+C14-C15-C16+C17+C18 -> 3235 | D19: =D13+D14-D15-D16+D17+D18 -> 3407 | E19: =E13+E14-E15-E16+E17+E18 -> 3583 | F19: =F13+F14-F15-F16+F17+F18 -> 3769 | H19: E(Equity) | I19: 5437 | J19: 5835 | K19: 6259 | L19: 6707 | M19: 7180
A20: Duality of FCFF | B20: ='Balance Sheet'!G142+'Balance Sheet'!G116+'Balance Sheet'!G104+'Income Statement'!K79+ROUND('Income Statement'!K50*0.7103,0)-('Balance Sheet'!T142+'Balance Sheet'!T116+'Balance Sheet'!T104) -> 3085 | C20: ='Balance Sheet'!T142+'Balance Sheet'!T116+'Balance Sheet'!T104+'Income Statement'!L79+ROUND('Income Statement'!L50*0.7103,0)-('Balance Sheet'!U142+'Balance Sheet'!U116+'Balance Sheet'!U104) -> 3123 | D20: ='Balance Sheet'!U142+'Balance Sheet'!U116+'Balance Sheet'!U104+'Income Statement'!M79+ROUND('Income Statement'!M50*0.7103,0)-('Balance Sheet'!V142+'Balance Sheet'!V116+'Balance Sheet'!V104) -> 3310 | E20: ='Balance Sheet'!V142+'Balance Sheet'!V116+'Balance Sheet'!V104+'Income Statement'!N79+ROUND('Income Statement'!N50*0.7103,0)-('Balance Sheet'!W142+'Balance Sheet'!W116+'Balance Sheet'!W104) -> 3494 | F20: ='Balance Sheet'!W142+'Balance Sheet'!W116+'Balance Sheet'!W104+'Income Statement'!O79+ROUND('Income Statement'!O50*0.7103,0)-('Balance Sheet'!X142+'Balance Sheet'!X116+'Balance Sheet'!X104) -> 3681 | H20: D (Total Debt) | I20: 5843 | J20: 5961 | K20: 6708 | L20: 6196 | M20: 6314
H21: V = E + D | I21: =I19+I20 -> 11280 | J21: =J19+J20 -> 11796 | K21: =K19+K20 -> 12967 | L21: =L19+L20 -> 12903 | M21: =M19+M20 -> 13494
H22: E/V | I22: =I19/I21 -> 0.48200355 | J22: =J19/J21 -> 0.49465921 | K22: =K19/K21 -> 0.48268682 | L22: =L19/L21 -> 0.5198016 | M22: =M19/M21 -> 0.53208834
H23: D/V | I23: =I20/I21 -> 0.51799645 | J23: =J20/J21 -> 0.50534079 | K23: =K20/K21 -> 0.51731318 | L23: =L20/L21 -> 0.4801984 | M23: =M20/M21 -> 0.46791166
H24: Cost of Debt(Kd) | I24: 0.0335 | J24: 0.0335 | K24: 0.0335 | L24: 0.0335 | M24: 0.0335
H25: Tax Rate | I25: 0.2908 | J25: 0.2931 | K25: 0.2954 | L25: 0.2977 | M25: 0.3
H26: WACC | I26: =(I22*I18)+(I23*I24*(1-I25)) -> 0.058272939 | J26: =(J22*J18)+(J23*J24*(1-J25)) -> 0.058418127 | K26: =(K22*K18)+(K23*K24*(1-K25)) -> 0.056866971 | L26: =(L22*L18)+(L23*L24*(1-L25)) -> 0.058711855 | M26: =(M22*M18)+(M23*M24*(1-M25)) -> 0.058857399
H27: Long-term growth rate | I27: 0.0125 | J27: 0.0125 | K27: 0.0125 | L27: 0.0125 | M27: 0.0125
H28: YEAR | I28: t | J28: FCFF | K28: PV of Each years FCFF
H29: 2026 | I29: 1 | J29: =B19 -> 3507 | K29: =J29/(1+I26)^1 -> 3313.8899
H30: 2027 | I30: 2 | J30: =C19 -> 3235 | K30: =J30/(1+J26)^2 -> 2887.751
H31: 2028 | I31: 3 | J31: =D19 -> 3407 | K31: =J31/(1+K26)^3 -> 2886.0985
H32: 2029 | I32: 4 | J32: =E19 -> 3583 | K32: =J32/(1+L26)^4 -> 2851.9093
H33: 2030 | I33: 5 | J33: =F19 -> 3769 | K33: =J33/(1+M26)^5 -> 2831.6447
H34: Terminal Value | K34: =J33*(1+0.0125)/(M26-0.0125) -> 82319.383
H35: PVTV | K35: =K34/(1+M26)^5 -> 61846.443
H36: Total Present Value of Firm | K36: =K29+K30+K31+K32+K33+K35 -> 76617.737
H37: Value of debt | K37: ='Balance Sheet'!G116+'Balance Sheet'!G104 -> 5868
H38: Value of equity | K38: =K36-K37 -> 70749.737
H39: Number of shares (m) | K39: 1140
H40: Price per share | K40: =K38/K39 -> 62.061173
...

Sheet FCFF
A1: Free Cash Flow to the Firm (FCFF) — Wesfarmers Ltd (WES.AX)
A2: AUD $m | FY2026–FY2030 | All components formula-linked to pro-forma IS and BS | Duality checks for both FCFE and FCFF
A4: SECTION 1 — FCFF FORMULA & RELATIONSHIP TO FCFE
A5: FCFF = E + NCC − ΔWCAP − FCInv + Interest×(1−T) + Δ Other NCL
A6: FCFF = FCFE + Interest×(1−T) − Net Borrowing (key relationship)
A7: Where:
A8: E = Net Income | B8: IS row 79 — same as FCFE
A9: NCC = Non-Cash Charges (Dep + Amort) | B9: IS rows 30+29 — same as FCFE
A10: ΔWCAP = Change in Net Working Capital | B10: BS rows 35,20,113,104 — same as FCFE
A11: FCInv = Net Capital Expenditure | B11: BS row 41 + IS row 30 — same as FCFE
A12: Interest×(1−T) = After-tax interest expense | B12: IS row 50 × (1−avg tax rate) = IS row 50 × 0.7103
A13: Δ Other NCL = Change in other non-current liabilities | B13: BS row 120 — same as FCFE
A14: Note: Net Borrowing is EXCLUDED — FCFF is pre-financing (available to ALL capital providers) | B14: Net Borrowing is a financing decision, not part of the firm's operating free cash flow
A16: SECTION 2 — FCFF CALCULATION (FY2026–FY2030)
A17: Component | B17: 2026 | C17: 2027 | D17: 2028 | E17: 2029 | F17: 2030 | H17: Formula / Source Reference
